Workbook

Sheet DataSet
A1: Row ID | B1: Order ID | C1: Order Date | D1: Ship Date | E1: Ship Mode | F1: Customer ID | G1: Customer Name | H1: Segment | I1: Country | J1: City | K1: State | L1: Postal Code | M1: Region | N1: Product ID | O1: Category | P1: Sub-Category | Q1: Product Name | R1: Sales | S1: Quantity | T1: Discount | U1: Profit | V1: Ship Mode Imputed | W1: Segment Imputed | X1: City and State | Y1: Sub-Category Imputed | Z1: Sales price Imputed W category | AA1: Sales W Sub Category | AB1: Total Sales | AC1: Total Sales W Discount | AD1: Country Code | AE1: Order Year | AF1: Order ID2
A2: 1 | B2: CA-2016-152156 | C2: 42682 | D2: 42685 | E2: Second Class | F2: CG-12520 | G2: Claire Gute | H2: Consumer | I2: United States | J2: Henderson | K2: Kentucky | L2: 42420 | M2: South | N2: FUR-BO-10001798 | O2: Furniture | P2: Bookcases | Q2: Bush Somerset Collection Bookcase | R2: 261.96 | S2: 2 | T2: 0 | U2: 41.9136 | V2: =IF(ISBLANK(E2),"UNKNOWN",E2) -> Second Class | W2: =IF(ISBLANK(H2),"UNKNOWN",H2) -> Consumer | X2: =CONCATENATE(J2," - ",K2) -> Henderson - Kentucky | Y2: =IF(ISBLANK(P2),"UNKNOWN",P2) -> Bookcases | Z2: =IF(ISBLANK(R2),ROUND(AVERAGEIF($O$2:$O$600,O2,$R$2:$R$29),0),R2) -> 261.96 | AA2: =IF(ISBLANK(R2),ROUND(AVERAGEIF($Y$2:$Y$600,Y2,$R$2:$R$29),0),R2) -> 261.96 | AB2: =AA2*S2 -> 523.92 | AC2: =AB2*(1-T2) -> 523.92 | AD2: CA | AE2: =MID(B2,4,4) -> 2016 | AF2: =RIGHT(B2,6) -> 152156
A3: 2 | B3: CA-2016-152156 | C3: 42682 | D3: 42685 | E3: Second Class | F3: CG-12520 | G3: Claire Gute | H3: Consumer | I3: United States | J3: Henderson | K3: Kentucky | L3: 42420 | M3: South | N3: FUR-CH-10000454 | O3: Furniture | P3: Chairs | Q3: Hon Deluxe Fabric Upholstered Stacking Chairs, Rounded Back | R3: 731.94 | S3: 3 | T3: 0 | U3: 219.582 | V3: =IF(ISBLANK(E3),"UNKNOWN",E3) -> Second Class | W3: =IF(ISBLANK(H3),"UNKNOWN",H3) -> Consumer | X3: =CONCATENATE(J3," - ",K3) -> Henderson - Kentucky | Y3: =IF(ISBLANK(P3),"UNKNOWN",P3) -> Chairs | Z3: =IF(ISBLANK(R3),ROUND(AVERAGEIF($O$2:$O$600,O3,$R$2:$R$29),0),R3) -> 731.94 | AA3: =IF(ISBLANK(R3),ROUND(AVERAGEIF($Y$2:$Y$600,Y3,$R$2:$R$29),0),R3) -> 731.94 | AB3: =AA3*S3 -> 2195.82 | AC3: =AB3*(1-T3) -> 2195.82 | AD3: CA | AE3: =MID(B3,4,4) -> 2016 | AF3: =RIGHT(B3,6) -> 152156
A4: 3 | B4: CA-2016-138688 | C4: 42533 | D4: 42537 | E4: Second Class | F4: DV-13045 | G4: Darrin Van Huff | H4: Corporate | I4: United States | J4: Los Angeles | K4: California | L4: 90036 | M4: West | N4: OFF-LA-10000240 | O4: Office Supplies | P4: Labels | Q4: Self-Adhesive Address Labels for Typewriters by Universal | R4: 14.62 | S4: 2 | T4: 0 | U4: 6.8714 | V4: =IF(ISBLANK(E4),"UNKNOWN",E4) -> Second Class | W4: =IF(ISBLANK(H4),"UNKNOWN",H4) -> Corporate | X4: =CONCATENATE(J4," - ",K4) -> Los Angeles - California | Y4: =IF(ISBLANK(P4),"UNKNOWN",P4) -> Labels | Z4: =IF(ISBLANK(R4),ROUND(AVERAGEIF($O$2:$O$600,O4,$R$2:$R$29),0),R4) -> 14.62 | AA4: =IF(ISBLANK(R4),ROUND(AVERAGEIF($Y$2:$Y$600,Y4,$R$2:$R$29),0),R4) -> 14.62 | AB4: =AA4*S4 -> 29.24 | AC4: =AB4*(1-T4) -> 29.24 | AD4: CA | AE4: =MID(B4,4,4) -> 2016 | AF4: =RIGHT(B4,6) -> 138688
A5: 4 | B5: US-2015-108966 | C5: 42288 | D5: 42295 | E5: Standard Class | F5: SO-20335 | G5: Sean O'Donnell | H5: Consumer | I5: United States | J5: Fort Lauderdale | K5: Florida | L5: 33311 | M5: South | N5: FUR-TA-10000577 | O5: Furniture | P5: Tables | Q5: Bretford CR4500 Series Slim Rectangular Table | R5: 957.5775 | S5: 5 | T5: 0.45 | U5: -383.031 | V5: =IF(ISBLANK(E5),"UNKNOWN",E5) -> Standard Class | W5: =IF(ISBLANK(H5),"UNKNOWN",H5) -> Consumer | X5: =CONCATENATE(J5," - ",K5) -> Fort Lauderdale - Florida | Y5: =IF(ISBLANK(P5),"UNKNOWN",P5) -> Tables | Z5: =IF(ISBLANK(R5),ROUND(AVERAGEIF($O$2:$O$600,O5,$R$2:$R$29),0),R5) -> 957.5775 | AA5: =IF(ISBLANK(R5),ROUND(AVERAGEIF($Y$2:$Y$600,Y5,$R$2:$R$29),0),R5) -> 957.5775 | AB5: =AA5*S5 -> 4787.8875 | AC5: =AB5*(1-T5) -> 2633.3381 | AD5: US | AE5: =MID(B5,4,4) -> 2015 | AF5: =RIGHT(B5,6) -> 108966
A6: 5 | B6: US-2015-108966 | C6: 42288 | D6: 42295 | E6: Standard Class | F6: SO-20335 | G6: Sean O'Donnell | H6: Consumer | I6: United States | J6: Fort Lauderdale | K6: Florida | L6: 33311 | M6: South | N6: OFF-ST-10000760 | O6: Office Supplies | P6: Storage | Q6: Eldon Fold 'N Roll Cart System | R6: 22.368 | S6: 2 | T6: 0.2 | U6: 2.5164 | V6: =IF(ISBLANK(E6),"UNKNOWN",E6) -> Standard Class | W6: =IF(ISBLANK(H6),"UNKNOWN",H6) -> Consumer | X6: =CONCATENATE(J6," - ",K6) -> Fort Lauderdale - Florida | Y6: =IF(ISBLANK(P6),"UNKNOWN",P6) -> Storage | Z6: =IF(ISBLANK(R6),ROUND(AVERAGEIF($O$2:$O$600,O6,$R$2:$R$29),0),R6) -> 22.368 | AA6: =IF(ISBLANK(R6),ROUND(AVERAGEIF($Y$2:$Y$600,Y6,$R$2:$R$29),0),R6) -> 22.368 | AB6: =AA6*S6 -> 44.736 | AC6: =AB6*(1-T6) -> 35.7888 | AD6: US | AE6: =MID(B6,4,4) -> 2015 | AF6: =RIGHT(B6,6) -> 108966
A7: 6 | B7: CA-2014-115812 | C7: 41799 | D7: 41804 | E7: Standard Class | F7: BH-11710 | G7: Brosina Hoffman | H7: Consumer | I7: United States | J7: Los Angeles | K7: California | L7: 90032 | M7: West | N7: FUR-FU-10001487 | O7: Furniture | P7: Furnishings | Q7: Eldon Expressions Wood and Plastic Desk Accessories, Cherry Wood | R7: 48.86 | S7: 7 | T7: 0 | U7: 14.1694 | V7: =IF(ISBLANK(E7),"UNKNOWN",E7) -> Standard Class | W7: =IF(ISBLANK(H7),"UNKNOWN",H7) -> Consumer | X7: =CONCATENATE(J7," - ",K7) -> Los Angeles - California | Y7: =IF(ISBLANK(P7),"UNKNOWN",P7) -> Furnishings | Z7: =IF(ISBLANK(R7),ROUND(AVERAGEIF($O$2:$O$600,O7,$R$2:$R$29),0),R7) -> 48.86 | AA7: =IF(ISBLANK(R7),ROUND(AVERAGEIF($Y$2:$Y$600,Y7,$R$2:$R$29),0),R7) -> 48.86 | AB7: =AA7*S7 -> 342.02 | AC7: =AB7*(1-T7) -> 342.02 | AD7: CA | AE7: =MID(B7,4,4) -> 2014 | AF7: =RIGHT(B7,6) -> 115812
A8: 7 | B8: CA-2014-115812 | C8: 41799 | D8: 41804 | E8: Standard Class | F8: BH-11710 | G8: Brosina Hoffman | H8: Consumer | I8: United States | J8: Los Angeles | K8: California | L8: 90032 | M8: West | N8: OFF-AR-10002833 | O8: Office Supplies | P8: Art | Q8: Newell 322 | R8: 7.28 | S8: 4 | T8: 0 | U8: 1.9656 | V8: =IF(ISBLANK(E8),"UNKNOWN",E8) -> Standard Class | W8: =IF(ISBLANK(H8),"UNKNOWN",H8) -> Consumer | X8: =CONCATENATE(J8," - ",K8) -> Los Angeles - California | Y8: =IF(ISBLANK(P8),"UNKNOWN",P8) -> Art | Z8: =IF(ISBLANK(R8),ROUND(AVERAGEIF($O$2:$O$600,O8,$R$2:$R$29),0),R8) -> 7.28 | AA8: =IF(ISBLANK(R8),ROUND(AVERAGEIF($Y$2:$Y$600,Y8,$R$2:$R$29),0),R8) -> 7.28 | AB8: =AA8*S8 -> 29.12 | AC8: =AB8*(1-T8) -> 29.12 | AD8: CA | AE8: =MID(B8,4,4) -> 2014 | AF8: =RIGHT(B8,6) -> 115812
A9: 8 | B9: CA-2014-115812 | C9: 41799 | D9: 41804 | E9: Standard Class | F9: BH-11710 | G9: Brosina Hoffman | H9: Consumer | I9: United States | J9: Los Angeles | K9: California | L9: 90032 | M9: West | N9: TEC-PH-10002275 | O9: Technology | P9: Phones | Q9: Mitel 5320 IP Phone VoIP phone | R9: 907.152 | S9: 6 | T9: 0.2 | U9: 90.7152 | V9: =IF(ISBLANK(E9),"UNKNOWN",E9) -> Standard Class | W9: =IF(ISBLANK(H9),"UNKNOWN",H9) -> Consumer | X9: =CONCATENATE(J9," - ",K9) -> Los Angeles - California | Y9: =IF(ISBLANK(P9),"UNKNOWN",P9) -> Phones | Z9: =IF(ISBLANK(R9),ROUND(AVERAGEIF($O$2:$O$600,O9,$R$2:$R$29),0),R9) -> 907.152 | AA9: =IF(ISBLANK(R9),ROUND(AVERAGEIF($Y$2:$Y$600,Y9,$R$2:$R$29),0),R9) -> 907.152 | AB9: =AA9*S9 -> 5442.912 | AC9: =AB9*(1-T9) -> 4354.3296 | AD9: CA | AE9: =MID(B9,4,4) -> 2014 | AF9: =RIGHT(B9,6) -> 115812
A10: 9 | B10: CA-2014-115812 | C10: 41799 | D10: 41804 | E10: Standard Class | F10: BH-11710 | G10: Brosina Hoffman | H10: Consumer | I10: United States | J10: Los Angeles | K10: California | L10: 90032 | M10: West | N10: OFF-BI-10003910 | O10: Office Supplies | P10: Binders | Q10: DXL Angle-View Binders with Locking Rings by Samsill | R10: 18.504 | S10: 3 | T10: 0.2 | U10: 5.7825 | V10: =IF(ISBLANK(E10),"UNKNOWN",E10) -> Standard Class | W10: =IF(ISBLANK(H10),"UNKNOWN",H10) -> Consumer | X10: =CONCATENATE(J10," - ",K10) -> Los Angeles - California | Y10: =IF(ISBLANK(P10),"UNKNOWN",P10) -> Binders | Z10: =IF(ISBLANK(R10),ROUND(AVERAGEIF($O$2:$O$600,O10,$R$2:$R$29),0),R10) -> 18.504 | AA10: =IF(ISBLANK(R10),ROUND(AVERAGEIF($Y$2:$Y$600,Y10,$R$2:$R$29),0),R10) -> 18.504 | AB10: =AA10*S10 -> 55.512 | AC10: =AB10*(1-T10) -> 44.4096 | AD10: CA | AE10: =MID(B10,4,4) -> 2014 | AF10: =RIGHT(B10,6) -> 115812
A11: 10 | B11: CA-2014-115812 | C11: 41799 | D11: 41804 | E11: Standard Class | F11: BH-11710 | G11: Brosina Hoffman | H11: Consumer | I11: United States | J11: Los Angeles | K11: California | L11: 90032 | M11: West | N11: OFF-AP-10002892 | O11: Office Supplies | P11: Appliances | Q11: Belkin F5C206VTEL 6 Outlet Surge | R11: 114.9 | S11: 5 | T11: 0 | U11: 34.47 | V11: =IF(ISBLANK(E11),"UNKNOWN",E11) -> Standard Class | W11: =IF(ISBLANK(H11),"UNKNOWN",H11) -> Consumer | X11: =CONCATENATE(J11," - ",K11) -> Los Angeles - California | Y11: =IF(ISBLANK(P11),"UNKNOWN",P11) -> Appliances | Z11: =IF(ISBLANK(R11),ROUND(AVERAGEIF($O$2:$O$600,O11,$R$2:$R$29),0),R11) -> 114.9 | AA11: =IF(ISBLANK(R11),ROUND(AVERAGEIF($Y$2:$Y$600,Y11,$R$2:$R$29),0),R11) -> 114.9 | AB11: =AA11*S11 -> 574.5 | AC11: =AB11*(1-T11) -> 574.5 | AD11: CA | AE11: =MID(B11,4,4) -> 2014 | AF11: =RIGHT(B11,6) -> 115812
A12: 11 | B12: CA-2014-115812 | C12: 41799 | D12: 41804 | E12: Standard Class | F12: BH-11710 | G12: Brosina Hoffman | H12: Consumer | I12: United States | J12: Los Angeles | K12: California | L12: 90032 | M12: West | N12: FUR-TA-10001539 | O12: Furniture | P12: Tables | Q12: Chromcraft Rectangular Conference Tables | R12: 1706.184 | S12: 9 | T12: 0.2 | U12: 85.3092 | V12: =IF(ISBLANK(E12),"UNKNOWN",E12) -> Standard Class | W12: =IF(ISBLANK(H12),"UNKNOWN",H12) -> Consumer | X12: =CONCATENATE(J12," - ",K12) -> Los Angeles - California | Y12: =IF(ISBLANK(P12),"UNKNOWN",P12) -> Tables | Z12: =IF(ISBLANK(R12),ROUND(AVERAGEIF($O$2:$O$600,O12,$R$2:$R$29),0),R12) -> 1706.184 | AA12: =IF(ISBLANK(R12),ROUND(AVERAGEIF($Y$2:$Y$600,Y12,$R$2:$R$29),0),R12) -> 1706.184 | AB12: =AA12*S12 -> 15355.656 | AC12: =AB12*(1-T12) -> 12284.525 | AD12: CA | AE12: =MID(B12,4,4) -> 2014 | AF12: =RIGHT(B12,6) -> 115812
A13: 12 | B13: CA-2014-115812 | C13: 41799 | D13: 41804 | E13: Standard Class | F13: BH-11710 | G13: Brosina Hoffman | H13: Consumer | I13: United States | J13: Los Angeles | K13: California | L13: 90032 | M13: West | N13: TEC-PH-10002033 | O13: Technology | P13: Phones | Q13: Konftel 250 Conference phone - Charcoal black | R13: 911.424 | S13: 4 | T13: 0.2 | U13: 68.3568 | V13: =IF(ISBLANK(E13),"UNKNOWN",E13) -> Standard Class | W13: =IF(ISBLANK(H13),"UNKNOWN",H13) -> Consumer | X13: =CONCATENATE(J13," - ",K13) -> Los Angeles - California | Y13: =IF(ISBLANK(P13),"UNKNOWN",P13) -> Phones | Z13: =IF(ISBLANK(R13),ROUND(AVERAGEIF($O$2:$O$600,O13,$R$2:$R$29),0),R13) -> 911.424 | AA13: =IF(ISBLANK(R13),ROUND(AVERAGEIF($Y$2:$Y$600,Y13,$R$2:$R$29),0),R13) -> 911.424 | AB13: =AA13*S13 -> 3645.696 | AC13: =AB13*(1-T13) -> 2916.5568 | AD13: CA | AE13: =MID(B13,4,4) -> 2014 | AF13: =RIGHT(B13,6) -> 115812
... A15: 14 | B15: CA-2016-161389 | C15: 42709 | D15: 42714 | E15: Standard Class | F15: IM-15070 | G15: Irene Maddox | H15: Consumer | I15: United States | J15: Seattle | K15: Washington | L15: 98103 | M15: West | N15: OFF-BI-10003656 | O15: Office Supplies | P15: Binders | Q15: Fellowes PB200 Plastic Comb Binding Machine | R15: 407.976 | S15: 3 | T15: 0.2 | U15: 132.5922 | V15: =IF(ISBLANK(E15),"UNKNOWN",E15) -> Standard Class | W15: =IF(ISBLANK(H15),"UNKNOWN",H15) -> Consumer | X15: =CONCATENATE(J15," - ",K15) -> Seattle - Washington | Y15: =IF(ISBLANK(P15),"UNKNOWN",P15) -> Binders | Z15: =IF(ISBLANK(R15),ROUND(AVERAGEIF($O$2:$O$600,O15,$R$2:$R$29),0),R15) -> 407.976 | AA15: =IF(ISBLANK(R15),ROUND(AVERAGEIF($Y$2:$Y$600,Y15,$R$2:$R$29),0),R15) -> 407.976 | AB15: =AA15*S15 -> 1223.928 | AC15: =AB15*(1-T15) -> 979.1424 | AD15: CA | AE15: =MID(B15,4,4) -> 2016 | AF15: =RIGHT(B15,6) -> 161389
A16: 15 | B16: US-2015-118983 | C16: 42330 | D16: 42334 | F16: HP-14815 | G16: Harold Pawlan | H16: Home Office | I16: United States | J16: Fort Worth | K16: Texas | L16: 76106 | M16: Central | N16: OFF-AP-10002311 | O16: Office Supplies | P16: Appliances | Q16: Holmes Replacement Filter for HEPA Air Cleaner, Very Large Room, HEPA Filter | R16: 68.81 | S16: 5 | T16: 0.8 | U16: -123.858 | V16: =IF(ISBLANK(E16),"UNKNOWN",E16) -> UNKNOWN | W16: =IF(ISBLANK(H16),"UNKNOWN",H16) -> Home Office | X16: =CONCATENATE(J16," - ",K16) -> Fort Worth - Texas | Y16: =IF(ISBLANK(P16),"UNKNOWN",P16) -> Appliances | Z16: =IF(ISBLANK(R16),ROUND(AVERAGEIF($O$2:$O$600,O16,$R$2:$R$29),0),R16) -> 68.81 | AA16: =IF(ISBLANK(R16),ROUND(AVERAGEIF($Y$2:$Y$600,Y16,$R$2:$R$29),0),R16) -> 68.81 | AB16: =AA16*S16 -> 344.05 | AC16: =AB16*(1-T16) -> 68.81 | AD16: US | AE16: =MID(B16,4,4) -> 2015 | AF16: =RIGHT(B16,6) -> 118983
A17: 16 | B17: US-2015-118983 | C17: 42330 | D17: 42334 | E17: Standard Class | F17: HP-14815 | G17: Harold Pawlan | H17: Home Office | I17: United States | J17: Fort Worth | K17: Texas | L17: 76106 | M17: Central | N17: OFF-BI-10000756 | O17: Office Supplies | P17: Binders | Q17: Storex DuraTech Recycled Plastic Frosted Binders | R17: 2.544 | S17: 3 | T17: 0.8 | U17: -3.816 | V17: =IF(ISBLANK(E17),"UNKNOWN",E17) -> Standard Class | W17: =IF(ISBLANK(H17),"UNKNOWN",H17) -> Home Office | X17: =CONCATENATE(J17," - ",K17) -> Fort Worth - Texas | Y17: =IF(ISBLANK(P17),"UNKNOWN",P17) -> Binders | Z17: =IF(ISBLANK(R17),ROUND(AVERAGEIF($O$2:$O$600,O17,$R$2:$R$29),0),R17) -> 2.544 | AA17: =IF(ISBLANK(R17),ROUND(AVERAGEIF($Y$2:$Y$600,Y17,$R$2:$R$29),0),R17) -> 2.544 | AB17: =AA17*S17 -> 7.632 | AC17: =AB17*(1-T17) -> 1.5264 | AD17: US | AE17: =MID(B17,4,4) -> 2015 | AF17: =RIGHT(B17,6) -> 118983
A18: 17 | B18: CA-2014-105893 | C18: 41954 | D18: 41961 | E18: Standard Class | F18: PK-19075 | G18: Pete Kriz | H18: Consumer | I18: United States | J18: Madison | K18: Wisconsin | L18: 53711 | M18: Central | N18: OFF-ST-10004186 | O18: Office Supplies | P18: Storage | Q18: Stur-D-Stor Shelving, Vertical 5-Shelf: 72"H x 36"W x 18 1/2"D | R18: 665.88 | S18: 6 | T18: 0 | U18: 13.3176 | V18: =IF(ISBLANK(E18),"UNKNOWN",E18) -> Standard Class | W18: =IF(ISBLANK(H18),"UNKNOWN",H18) -> Consumer | X18: =CONCATENATE(J18," - ",K18) -> Madison - Wisconsin | Y18: =IF(ISBLANK(P18),"UNKNOWN",P18) -> Storage | Z18: =IF(ISBLANK(R18),ROUND(AVERAGEIF($O$2:$O$600,O18,$R$2:$R$29),0),R18) -> 665.88 | AA18: =IF(ISBLANK(R18),ROUND(AVERAGEIF($Y$2:$Y$600,Y18,$R$2:$R$29),0),R18) -> 665.88 | AB18: =AA18*S18 -> 3995.28 | AC18: =AB18*(1-T18) -> 3995.28 | AD18: CA | AE18: =MID(B18,4,4) -> 2014 | AF18: =RIGHT(B18,6) -> 105893
A19: 18 | B19: CA-2014-167164 | C19: 41772 | D19: 41774 | E19: Second Class | F19: AG-10270 | G19: Alejandro Grove | H19: Consumer | I19: United States | J19: West Jordan | K19: Utah | L19: 84084 | M19: West | N19: OFF-ST-10000107 | O19: Office Supplies | P19: Storage | Q19: Fellowes Super Stor/Drawer | R19: 55.5 | S19: 2 | T19: 0 | U19: 9.99 | V19: =IF(ISBLANK(E19),"UNKNOWN",E19) -> Second Class | W19: =IF(ISBLANK(H19),"UNKNOWN",H19) -> Consumer | X19: =CONCATENATE(J19," - ",K19) -> West Jordan - Utah | Y19: =IF(ISBLANK(P19),"UNKNOWN",P19) -> Storage | Z19: =IF(ISBLANK(R19),ROUND(AVERAGEIF($O$2:$O$600,O19,$R$2:$R$29),0),R19) -> 55.5 | AA19: =IF(ISBLANK(R19),ROUND(AVERAGEIF($Y$2:$Y$600,Y19,$R$2:$R$29),0),R19) -> 55.5 | AB19: =AA19*S19 -> 111 | AC19: =AB19*(1-T19) -> 111 | AD19: CA | AE19: =MID(B19,4,4) -> 2014 | AF19: =RIGHT(B19,6) -> 167164
A20: 19 | B20: CA-2014-143336 | C20: 41878 | D20: 41883 | E20: Second Class | F20: ZD-21925 | G20: Zuschuss Donatelli | H20: Consumer | I20: United States | J20: San Francisco | K20: California | L20: 94109 | M20: West | N20: OFF-AR-10003056 | O20: Office Supplies | P20: Art | Q20: Newell 341 | R20: 8.56 | S20: 2 | T20: 0 | U20: 2.4824 | V20: =IF(ISBLANK(E20),"UNKNOWN",E20) -> Second Class | W20: =IF(ISBLANK(H20),"UNKNOWN",H20) -> Consumer | X20: =CONCATENATE(J20," - ",K20) -> San Francisco - California | Y20: =IF(ISBLANK(P20),"UNKNOWN",P20) -> Art | Z20: =IF(ISBLANK(R20),ROUND(AVERAGEIF($O$2:$O$600,O20,$R$2:$R$29),0),R20) -> 8.56 | AA20: =IF(ISBLANK(R20),ROUND(AVERAGEIF($Y$2:$Y$600,Y20,$R$2:$R$29),0),R20) -> 8.56 | AB20: =AA20*S20 -> 17.12 | AC20: =AB20*(1-T20) -> 17.12 | AD20: CA | AE20: =MID(B20,4,4) -> 2014 | AF20: =RIGHT(B20,6) -> 143336
A21: 20 | B21: CA-2014-143336 | C21: 41878 | D21: 41883 | E21: Second Class | F21: ZD-21925 | G21: Zuschuss Donatelli | H21: Consumer | I21: United States | J21: San Francisco | K21: California | L21: 94109 | M21: West | N21: TEC-PH-10001949 | O21: Technology | P21: Phones | Q21: Cisco SPA 501G IP Phone | R21: 213.48 | S21: 3 | T21: 0.2 | U21: 16.011 | V21: =IF(ISBLANK(E21),"UNKNOWN",E21) -> Second Class | W21: =IF(ISBLANK(H21),"UNKNOWN",H21) -> Consumer | X21: =CONCATENATE(J21," - ",K21) -> San Francisco - California | Y21: =IF(ISBLANK(P21),"UNKNOWN",P21) -> Phones | Z21: =IF(ISBLANK(R21),ROUND(AVERAGEIF($O$2:$O$600,O21,$R$2:$R$29),0),R21) -> 213.48 | AA21: =IF(ISBLANK(R21),ROUND(AVERAGEIF($Y$2:$Y$600,Y21,$R$2:$R$29),0),R21) -> 213.48 | AB21: =AA21*S21 -> 640.44 | AC21: =AB21*(1-T21) -> 512.352 | AD21: CA | AE21: =MID(B21,4,4) -> 2014 | AF21: =RIGHT(B21,6) -> 143336
A22: 21 | B22: CA-2014-143336 | C22: 41878 | D22: 41883 | E22: Second Class | F22: ZD-21925 | G22: Zuschuss Donatelli | H22: Consumer | I22: United States | J22: San Francisco | K22: California | L22: 94109 | M22: West | N22: OFF-BI-10002215 | O22: Office Supplies | Q22: Wilson Jones Hanging View Binder, White, 1" | R22: 22.72 | S22: 4 | T22: 0.2 | U22: 7.384 | V22: =IF(ISBLANK(E22),"UNKNOWN",E22) -> Second Class | W22: =IF(ISBLANK(H22),"UNKNOWN",H22) -> Consumer | X22: =CONCATENATE(J22," - ",K22) -> San Francisco - California | Y22: =IF(ISBLANK(P22),"UNKNOWN",P22) -> UNKNOWN | Z22: =IF(ISBLANK(R22),ROUND(AVERAGEIF($O$2:$O$600,O22,$R$2:$R$29),0),R22) -> 22.72 | AA22: =IF(ISBLANK(R22),ROUND(AVERAGEIF($Y$2:$Y$600,Y22,$R$2:$R$29),0),R22) -> 22.72 | AB22: =AA22*S22 -> 90.88 | AC22: =AB22*(1-T22) -> 72.704 | AD22: CA | AE22: =MID(B22,4,4) -> 2014 | AF22: =RIGHT(B22,6) -> 143336
A23: 22 | B23: CA-2016-137330 | C23: 42713 | D23: 42717 | E23: Standard Class | F23: KB-16585 | G23: Ken Black | H23: Corporate | I23: United States | J23: Fremont | K23: Nebraska | L23: 68025 | M23: Central | N23: OFF-AR-10000246 | O23: Office Supplies | P23: Art | Q23: Newell 318 | R23: 19.46 | S23: 7 | T23: 0 | U23: 5.0596 | V23: =IF(ISBLANK(E23),"UNKNOWN",E23) -> Standard Class | W23: =IF(ISBLANK(H23),"UNKNOWN",H23) -> Corporate | X23: =CONCATENATE(J23," - ",K23) -> Fremont - Nebraska | Y23: =IF(ISBLANK(P23),"UNKNOWN",P23) -> Art | Z23: =IF(ISBLANK(R23),ROUND(AVERAGEIF($O$2:$O$600,O23,$R$2:$R$29),0),R23) -> 19.46 | AA23: =IF(ISBLANK(R23),ROUND(AVERAGEIF($Y$2:$Y$600,Y23,$R$2:$R$29),0),R23) -> 19.46 | AB23: =AA23*S23 -> 136.22 | AC23: =AB23*(1-T23) -> 136.22 | AD23: CA | AE23: =MID(B23,4,4) -> 2016 | AF23: =RIGHT(B23,6) -> 137330
A24: 23 | B24: CA-2016-137330 | C24: 42713 | D24: 42717 | E24: Standard Class | F24: KB-16585 | G24: Ken Black | H24: Corporate | I24: United States | J24: Fremont | K24: Nebraska | L24: 68025 | M24: Central | N24: OFF-AP-10001492 | O24: Office Supplies | P24: Appliances | Q24: Acco Six-Outlet Power Strip, 4' Cord Length | R24: 60.34 | S24: 7 | T24: 0 | U24: 15.6884 | V24: =IF(ISBLANK(E24),"UNKNOWN",E24) -> Standard Class | W24: =IF(ISBLANK(H24),"UNKNOWN",H24) -> Corporate | X24: =CONCATENATE(J24," - ",K24) -> Fremont - Nebraska | Y24: =IF(ISBLANK(P24),"UNKNOWN",P24) -> Appliances | Z24: =IF(ISBLANK(R24),ROUND(AVERAGEIF($O$2:$O$600,O24,$R$2:$R$29),0),R24) -> 60.34 | AA24: =IF(ISBLANK(R24),ROUND(AVERAGEIF($Y$2:$Y$600,Y24,$R$2:$R$29),0),R24) -> 60.34 | AB24: =AA24*S24 -> 422.38 | AC24: =AB24*(1-T24) -> 422.38 | AD24: CA | AE24: =MID(B24,4,4) -> 2016 | AF24: =RIGHT(B24,6) -> 137330
A25: 24 | B25: US-2017-156909 | C25: 42932 | D25: 42934 | E25: Second Class | F25: SF-20065 | G25: Sandra Flanagan | H25: Consumer | I25: United States | J25: Philadelphia | K25: Pennsylvania | L25: 19140 | M25: East | N25: FUR-CH-10002774 | O25: Furniture | P25: Chairs | Q25: Global Deluxe Stacking Chair, Gray | R25: 71.372 | S25: 2 | T25: 0.3 | U25: -1.0196 | V25: =IF(ISBLANK(E25),"UNKNOWN",E25) -> Second Class | W25: =IF(ISBLANK(H25),"UNKNOWN",H25) -> Consumer | X25: =CONCATENATE(J25," - ",K25) -> Philadelphia - Pennsylvania | Y25: =IF(ISBLANK(P25),"UNKNOWN",P25) -> Chairs | Z25: =IF(ISBLANK(R25),ROUND(AVERAGEIF($O$2:$O$600,O25,$R$2:$R$29),0),R25) -> 71.372 | AA25: =IF(ISBLANK(R25),ROUND(AVERAGEIF($Y$2:$Y$600,Y25,$R$2:$R$29),0),R25) -> 71.372 | AB25: =AA25*S25 -> 142.744 | AC25: =AB25*(1-T25) -> 99.9208 | AD25: US | AE25: =MID(B25,4,4) -> 2017 | AF25: =RIGHT(B25,6) -> 156909
A26: 25 | B26: CA-2015-106320 | C26: 42272 | D26: 42277 | E26: Standard Class | F26: EB-13870 | G26: Emily Burns | H26: Consumer | I26: United States | J26: Orem | K26: Utah | L26: 84057 | M26: West | N26: FUR-TA-10000577 | O26: Furniture | P26: Tables | Q26: Bretford CR4500 Series Slim Rectangular Table | R26: 1044.63 | S26: 3 | T26: 0 | U26: 240.2649 | V26: =IF(ISBLANK(E26),"UNKNOWN",E26) -> Standard Class | W26: =IF(ISBLANK(H26),"UNKNOWN",H26) -> Consumer | X26: =CONCATENATE(J26," - ",K26) -> Orem - Utah | Y26: =IF(ISBLANK(P26),"UNKNOWN",P26) -> Tables | Z26: =IF(ISBLANK(R26),ROUND(AVERAGEIF($O$2:$O$600,O26,$R$2:$R$29),0),R26) -> 1044.63 | AA26: =IF(ISBLANK(R26),ROUND(AVERAGEIF($Y$2:$Y$600,Y26,$R$2:$R$29),0),R26) -> 1044.63 | AB26: =AA26*S26 -> 3133.89 | AC26: =AB26*(1-T26) -> 3133.89 | AD26: CA | AE26: =MID(B26,4,4) -> 2015 | AF26: =RIGHT(B26,6) -> 106320
A27: 26 | B27: CA-2016-121755 | C27: 42385 | D27: 42389 | E27: Second Class | F27: EH-13945 | G27: Eric Hoffmann | H27: Consumer | I27: United States | J27: Los Angeles | K27: California | L27: 90049 | M27: West | N27: OFF-BI-10001634 | O27: Office Supplies | P27: Binders | Q27: Wilson Jones Active Use Binders | R27: 11.648 | S27: 2 | T27: 0.2 | U27: 4.2224 | V27: =IF(ISBLANK(E27),"UNKNOWN",E27) -> Second Class | W27: =IF(ISBLANK(H27),"UNKNOWN",H27) -> Consumer | X27: =CONCATENATE(J27," - ",K27) -> Los Angeles - California | Y27: =IF(ISBLANK(P27),"UNKNOWN",P27) -> Binders | Z27: =IF(ISBLANK(R27),ROUND(AVERAGEIF($O$2:$O$600,O27,$R$2:$R$29),0),R27) -> 11.648 | AA27: =IF(ISBLANK(R27),ROUND(AVERAGEIF($Y$2:$Y$600,Y27,$R$2:$R$29),0),R27) -> 11.648 | AB27: =AA27*S27 -> 23.296 | AC27: =AB27*(1-T27) -> 18.6368 | AD27: CA | AE27: =MID(B27,4,4) -> 2016 | AF27: =RIGHT(B27,6) -> 121755
A28: 27 | B28: CA-2016-121755 | C28: 42385 | D28: 42389 | E28: Second Class | F28: EH-13945 | G28: Eric Hoffmann | H28: Consumer | I28: United States | J28: Los Angeles | K28: California | L28: 90049 | M28: West | N28: TEC-AC-10003027 | O28: Technology | P28: Accessories | Q28: Imation 8GB Mini TravelDrive USB 2.0 Flash Drive | R28: 90.57 | S28: 3 | T28: 0 | U28: 11.7741 | V28: =IF(ISBLANK(E28),"UNKNOWN",E28) -> Second Class | W28: =IF(ISBLANK(H28),"UNKNOWN",H28) -> Consumer | X28: =CONCATENATE(J28," - ",K28) -> Los Angeles - California | Y28: =IF(ISBLANK(P28),"UNKNOWN",P28) -> Accessories | Z28: =IF(ISBLANK(R28),ROUND(AVERAGEIF($O$2:$O$600,O28,$R$2:$R$29),0),R28) -> 90.57 | AA28: =IF(ISBLANK(R28),ROUND(AVERAGEIF($Y$2:$Y$600,Y28,$R$2:$R$29),0),R28) -> 90.57 | AB28: =AA28*S28 -> 271.71 | AC28: =AB28*(1-T28) -> 271.71 | AD28: CA | AE28: =MID(B28,4,4) -> 2016 | AF28: =RIGHT(B28,6) -> 121755
A29: 28 | B29: US-2015-150630 | C29: 42264 | D29: 42268 | E29: Standard Class | F29: TB-21520 | G29: Tracy Blumstein | H29: Consumer | I29: United States | J29: Philadelphia | K29: Pennsylvania | L29: 19140 | M29: East | N29: FUR-BO-10004834 | O29: Furniture | P29: Bookcases | Q29: Riverside Palais Royal Lawyers Bookcase, Royale Cherry Finish | R29: 3083.43 | S29: 7 | T29: 0.5 | U29: -1665.0522 | V29: =IF(ISBLANK(E29),"UNKNOWN",E29) -> Standard Class | W29: =IF(ISBLANK(H29),"UNKNOWN",H29) -> Consumer | X29: =CONCATENATE(J29," - ",K29) -> Philadelphia - Pennsylvania | Y29: =IF(ISBLANK(P29),"UNKNOWN",P29) -> Bookcases | Z29: =IF(ISBLANK(R29),ROUND(AVERAGEIF($O$2:$O$600,O29,$R$2:$R$29),0),R29) -> 3083.43 | AA29: =IF(ISBLANK(R29),ROUND(AVERAGEIF($Y$2:$Y$600,Y29,$R$2:$R$29),0),R29) -> 3083.43 | AB29: =AA29*S29 -> 21584.01 | AC29: =AB29*(1-T29) -> 10792.005 | AD29: US | AE29: =MID(B29,4,4) -> 2015 | AF29: =RIGHT(B29,6) -> 150630
A30: 29 | B30: US-2015-150630 | C30: 42264 | D30: 42268 | E30: Standard Class | F30: TB-21520 | G30: Tracy Blumstein | H30: Consumer | I30: United States | J30: Philadelphia | K30: Pennsylvania | L30: 19140 | M30: East | N30: OFF-BI-10000474 | O30: Office Supplies | P30: Binders | Q30: Avery Recycled Flexi-View Covers for Binding Systems | S30: 2 | T30: 0.7 | U30: -7.0532 | V30: =IF(ISBLANK(E30),"UNKNOWN",E30) -> Standard Class | W30: =IF(ISBLANK(H30),"UNKNOWN",H30) -> Consumer | X30: =CONCATENATE(J30," - ",K30) -> Philadelphia - Pennsylvania | Y30: =IF(ISBLANK(P30),"UNKNOWN",P30) -> Binders | Z30: =IF(ISBLANK(R30),ROUND(AVERAGEIF($O$2:$O$600,O30,$R$2:$R$29),0),R30) -> 124 | AA30: =IF(ISBLANK(R30),ROUND(AVERAGEIF($Y$2:$Y$600,Y30,$R$2:$R$29),0),R30) -> 190 | AB30: =AA30*S30 -> 380 | AC30: =AB30*(1-T30) -> 114 | AD30: US | AE30: =MID(B30,4,4) -> 2015 | AF30: =RIGHT(B30,6) -> 150630
A31: 30 | B31: US-2015-150630 | C31: 42264 | D31: 42268 | E31: Standard Class | F31: TB-21520 | G31: Tracy Blumstein | H31: Consumer | I31: United States | J31: Philadelphia | K31: Pennsylvania | L31: 19140 | M31: East | N31: FUR-FU-10004848 | O31: Furniture | P31: Furnishings | Q31: Howard Miller 13-3/4" Diameter Brushed Chrome Round Wall Clock | R31: 124.2 | S31: 3 | T31: 0.2 | U31: 15.525 | V31: =IF(ISBLANK(E31),"UNKNOWN",E31) -> Standard Class | W31: =IF(ISBLANK(H31),"UNKNOWN",H31) -> Consumer | X31: =CONCATENATE(J31," - ",K31) -> Philadelphia - Pennsylvania | Y31: =IF(ISBLANK(P31),"UNKNOWN",P31) -> Furnishings | Z31: =IF(ISBLANK(R31),ROUND(AVERAGEIF($O$2:$O$600,O31,$R$2:$R$29),0),R31) -> 124.2 | AA31: =IF(ISBLANK(R31),ROUND(AVERAGEIF($Y$2:$Y$600,Y31,$R$2:$R$29),0),R31) -> 124.2 | AB31: =AA31*S31 -> 372.6 | AC31: =AB31*(1-T31) -> 298.08 | AD31: US | AE31: =MID(B31,4,4) -> 2015 | AF31: =RIGHT(B31,6) -> 150630
A32: 31 | B32: US-2015-150630 | C32: 42264 | D32: 42268 | E32: Standard Class | F32: TB-21520 | G32: Tracy Blumstein | H32: Consumer | I32: United States | J32: Philadelphia | K32: Pennsylvania | L32: 19140 | M32: East | N32: OFF-EN-10001509 | O32: Office Supplies | P32: Envelopes | Q32: Poly String Tie Envelopes | R32: 3.264 | S32: 2 | T32: 0.2 | U32: 1.1016 | V32: =IF(ISBLANK(E32),"UNKNOWN",E32) -> Standard Class | W32: =IF(ISBLANK(H32),"UNKNOWN",H32) -> Consumer | X32: =CONCATENATE(J32," - ",K32) -> Philadelphia - Pennsylvania | Y32: =IF(ISBLANK(P32),"UNKNOWN",P32) -> Envelopes | Z32: =IF(ISBLANK(R32),ROUND(AVERAGEIF($O$2:$O$600,O32,$R$2:$R$29),0),R32) -> 3.264 | AA32: =IF(ISBLANK(R32),ROUND(AVERAGEIF($Y$2:$Y$600,Y32,$R$2:$R$29),0),R32) -> 3.264 | AB32: =AA32*S32 -> 6.528 | AC32: =AB32*(1-T32) -> 5.2224 | AD32: US | AE32: =MID(B32,4,4) -> 2015 | AF32: =RIGHT(B32,6) -> 150630
A33: 32 | B33: US-2015-150630 | C33: 42264 | D33: 42268 | E33: Standard Class | F33: TB-21520 | G33: Tracy Blumstein | H33: Consumer | I33: United States | J33: Philadelphia | K33: Pennsylvania | L33: 19140 | M33: East | N33: OFF-AR-10004042 | O33: Office Supplies | P33: Art | Q33: BOSTON Model 1800 Electric Pencil Sharpeners, Putty/Woodgrain | R33: 86.304 | S33: 6 | T33: 0.2 | U33: 9.7092 | V33: =IF(ISBLANK(E33),"UNKNOWN",E33) -> Standard Class | W33: =IF(ISBLANK(H33),"UNKNOWN",H33) -> Consumer | X33: =CONCATENATE(J33," - ",K33) -> Philadelphia - Pennsylvania | Y33: =IF(ISBLANK(P33),"UNKNOWN",P33) -> Art | Z33: =IF(ISBLANK(R33),ROUND(AVERAGEIF($O$2:$O$600,O33,$R$2:$R$29),0),R33) -> 86.304 | AA33: =IF(ISBLANK(R33),ROUND(AVERAGEIF($Y$2:$Y$600,Y33,$R$2:$R$29),0),R33) -> 86.304 | AB33: =AA33*S33 -> 517.824 | AC33: =AB33*(1-T33) -> 414.2592 | AD33: US | AE33: =MID(B33,4,4) -> 2015 | AF33: =RIGHT(B33,6) -> 150630
A34: 33 | B34: US-2015-150630 | C34: 42264 | D34: 42268 | E34: Standard Class | F34: TB-21520 | G34: Tracy Blumstein | H34: Consumer | I34: United States | J34: Philadelphia | K34: Pennsylvania | L34: 19140 | M34: East | N34: OFF-BI-10001525 | O34: Office Supplies | P34: Binders | Q34: Acco Pressboard Covers with Storage Hooks, 14 7/8" x 11", Executive Red | R34: 6.858 | S34: 6 | T34: 0.7 | U34: -5.715 | V34: =IF(ISBLANK(E34),"UNKNOWN",E34) -> Standard Class | W34: =IF(ISBLANK(H34),"UNKNOWN",H34) -> Consumer | X34: =CONCATENATE(J34," - ",K34) -> Philadelphia - Pennsylvania | Y34: =IF(ISBLANK(P34),"UNKNOWN",P34) -> Binders | Z34: =IF(ISBLANK(R34),ROUND(AVERAGEIF($O$2:$O$600,O34,$R$2:$R$29),0),R34) -> 6.858 | AA34: =IF(ISBLANK(R34),ROUND(AVERAGEIF($Y$2:$Y$600,Y34,$R$2:$R$29),0),R34) -> 6.858 | AB34: =AA34*S34 -> 41.148 | AC34: =AB34*(1-T34) -> 12.3444 | AD34: US | AE34: =MID(B34,4,4) -> 2015 | AF34: =RIGHT(B34,6) -> 150630
A35: 34 | B35: US-2015-150630 | C35: 42264 | D35: 42268 | E35: Standard Class | F35: TB-21520 | G35: Tracy Blumstein | H35: Consumer | I35: United States | J35: Philadelphia | K35: Pennsylvania | L35: 19140 | M35: East | N35: OFF-AR-10001683 | O35: Office Supplies | P35: Art | Q35: Lumber Crayons | R35: 15.76 | S35: 2 | T35: 0.2 | U35: 3.546 | V35: =IF(ISBLANK(E35),"UNKNOWN",E35) -> Standard Class | W35: =IF(ISBLANK(H35),"UNKNOWN",H35) -> Consumer | X35: =CONCATENATE(J35," - ",K35) -> Philadelphia - Pennsylvania | Y35: =IF(ISBLANK(P35),"UNKNOWN",P35) -> Art | Z35: =IF(ISBLANK(R35),ROUND(AVERAGEIF($O$2:$O$600,O35,$R$2:$R$29),0),R35) -> 15.76 | AA35: =IF(ISBLANK(R35),ROUND(AVERAGEIF($Y$2:$Y$600,Y35,$R$2:$R$29),0),R35) -> 15.76 | AB35: =AA35*S35 -> 31.52 | AC35: =AB35*(1-T35) -> 25.216 | AD35: US | AE35: =MID(B35,4,4) -> 2015 | AF35: =RIGHT(B35,6) -> 150630
A36: 35 | B36: CA-2017-107727 | C36: 43027 | D36: 43031 | E36: Second Class | F36: MA-17560 | G36: Matt Abelman | H36: Home Office | I36: United States | J36: Houston | K36: Texas | L36: 77095 | M36: Central | N36: OFF-PA-10000249 | O36: Office Supplies | P36: Paper | Q36: Easy-staple paper | R36: 29.472 | S36: 3 | T36: 0.2 | U36: 9.9468 | V36: =IF(ISBLANK(E36),"UNKNOWN",E36) -> Second Class | W36: =IF(ISBLANK(H36),"UNKNOWN",H36) -> Home Office | X36: =CONCATENATE(J36," - ",K36) -> Houston - Texas | Y36: =IF(ISBLANK(P36),"UNKNOWN",P36) -> Paper | Z36: =IF(ISBLANK(R36),ROUND(AVERAGEIF($O$2:$O$600,O36,$R$2:$R$29),0),R36) -> 29.472 | AA36: =IF(ISBLANK(R36),ROUND(AVERAGEIF($Y$2:$Y$600,Y36,$R$2:$R$29),0),R36) -> 29.472 | AB36: =AA36*S36 -> 88.416 | AC36: =AB36*(1-T36) -> 70.7328 | AD36: CA | AE36: =MID(B36,4,4) -> 2017 | AF36: =RIGHT(B36,6) -> 107727
A37: 36 | B37: CA-2016-117590 | C37: 42712 | D37: 42714 | E37: First Class | F37: GH-14485 | G37: Gene Hale | H37: Corporate | I37: United States | J37: Richardson | K37: Texas | L37: 75080 | M37: Central | N37: TEC-PH-10004977 | O37: Technology | P37: Phones | Q37: GE 30524EE4 | R37: 1097.544 | S37: 7 | T37: 0.2 | U37: 123.4737 | V37: =IF(ISBLANK(E37),"UNKNOWN",E37) -> First Class | W37: =IF(ISBLANK(H37),"UNKNOWN",H37) -> Corporate | X37: =CONCATENATE(J37," - ",K37) -> Richardson - Texas | Y37: =IF(ISBLANK(P37),"UNKNOWN",P37) -> Phones | Z37: =IF(ISBLANK(R37),ROUND(AVERAGEIF($O$2:$O$600,O37,$R$2:$R$29),0),R37) -> 1097.544 | AA37: =IF(ISBLANK(R37),ROUND(AVERAGEIF($Y$2:$Y$600,Y37,$R$2:$R$29),0),R37) -> 1097.544 | AB37: =AA37*S37 -> 7682.808 | AC37: =AB37*(1-T37) -> 6146.2464 | AD37: CA | AE37: =MID(B37,4,4) -> 2016 | AF37: =RIGHT(B37,6) -> 117590
A38: 37 | B38: CA-2016-117590 | C38: 42712 | D38: 42714 | E38: First Class | F38: GH-14485 | G38: Gene Hale | H38: Corporate | I38: United States | J38: Richardson | K38: Texas | L38: 75080 | M38: Central | N38: FUR-FU-10003664 | O38: Furniture | P38: Furnishings | Q38: Electrix Architect's Clamp-On Swing Arm Lamp, Black | R38: 190.92 | S38: 5 | T38: 0.6 | U38: -147.963 | V38: =IF(ISBLANK(E38),"UNKNOWN",E38) -> First Class | W38: =IF(ISBLANK(H38),"UNKNOWN",H38) -> Corporate | X38: =CONCATENATE(J38," - ",K38) -> Richardson - Texas | Y38: =IF(ISBLANK(P38),"UNKNOWN",P38) -> Furnishings | Z38: =IF(ISBLANK(R38),ROUND(AVERAGEIF($O$2:$O$600,O38,$R$2:$R$29),0),R38) -> 190.92 | AA38: =IF(ISBLANK(R38),ROUND(AVERAGEIF($Y$2:$Y$600,Y38,$R$2:$R$29),0),R38) -> 190.92 | AB38: =AA38*S38 -> 954.6 | AC38: =AB38*(1-T38) -> 381.84 | AD38: CA | AE38: =MID(B38,4,4) -> 2016 | AF38: =RIGHT(B38,6) -> 117590
A39: 38 | B39: CA-2015-117415 | C39: 42365 | D39: 42369 | E39: Standard Class | F39: SN-20710 | G39: Steve Nguyen | H39: Home Office | I39: United States | J39: Houston | K39: Texas | L39: 77041 | M39: Central | N39: OFF-EN-10002986 | O39: Office Supplies | P39: Envelopes | Q39: #10-4 1/8" x 9 1/2" Premium Diagonal Seam Envelopes | R39: 113.328 | S39: 9 | T39: 0.2 | U39: 35.415 | V39: =IF(ISBLANK(E39),"UNKNOWN",E39) -> Standard Class | W39: =IF(ISBLANK(H39),"UNKNOWN",H39) -> Home Office | X39: =CONCATENATE(J39," - ",K39) -> Houston - Texas | Y39: =IF(ISBLANK(P39),"UNKNOWN",P39) -> Envelopes | Z39: =IF(ISBLANK(R39),ROUND(AVERAGEIF($O$2:$O$600,O39,$R$2:$R$29),0),R39) -> 113.328 | AA39: =IF(ISBLANK(R39),ROUND(AVERAGEIF($Y$2:$Y$600,Y39,$R$2:$R$29),0),R39) -> 113.328 | AB39: =AA39*S39 -> 1019.952 | AC39: =AB39*(1-T39) -> 815.9616 | AD39: CA | AE39: =MID(B39,4,4) -> 2015 | AF39: =RIGHT(B39,6) -> 117415
A40: 39 | B40: CA-2015-117415 | C40: 42365 | D40: 42369 | E40: Standard Class | F40: SN-20710 | G40: Steve Nguyen | H40: Home Office | I40: United States | J40: Houston | K40: Texas | L40: 77041 | M40: Central | N40: FUR-BO-10002545 | O40: Furniture | P40: Bookcases | Q40: Atlantic Metals Mobile 3-Shelf Bookcases, Custom Colors | R40: 532.3992 | S40: 3 | T40: 0.32 | U40: -46.9764 | V40: =IF(ISBLANK(E40),"UNKNOWN",E40) -> Standard Class | W40: =IF(ISBLANK(H40),"UNKNOWN",H40) -> Home Office | X40: =CONCATENATE(J40," - ",K40) -> Houston - Texas | Y40: =IF(ISBLANK(P40),"UNKNOWN",P40) -> Bookcases | Z40: =IF(ISBLANK(R40),ROUND(AVERAGEIF($O$2:$O$600,O40,$R$2:$R$29),0),R40) -> 532.3992 | AA40: =IF(ISBLANK(R40),ROUND(AVERAGEIF($Y$2:$Y$600,Y40,$R$2:$R$29),0),R40) -> 532.3992 | AB40: =AA40*S40 -> 1597.1976 | AC40: =AB40*(1-T40) -> 1086.0944 | AD40: CA | AE40: =MID(B40,4,4) -> 2015 | AF40: =RIGHT(B40,6) -> 117415
A41: 40 | B41: CA-2015-117415 | C41: 42365 | D41: 42369 | E41: Standard Class | F41: SN-20710 | G41: Steve Nguyen | I41: United States | J41: Houston | K41: Texas | L41: 77041 | M41: Central | N41: FUR-CH-10004218 | O41: Furniture | P41: Chairs | Q41: Global Fabric Manager's Chair, Dark Gray | R41: 212.058 | S41: 3 | T41: 0.3 | U41: -15.147 | V41: =IF(ISBLANK(E41),"UNKNOWN",E41) -> Standard Class | W41: =IF(ISBLANK(H41),"UNKNOWN",H41) -> UNKNOWN | X41: =CONCATENATE(J41," - ",K41) -> Houston - Texas | Y41: =IF(ISBLANK(P41),"UNKNOWN",P41) -> Chairs | Z41: =IF(ISBLANK(R41),ROUND(AVERAGEIF($O$2:$O$600,O41,$R$2:$R$29),0),R41) -> 212.058 | AA41: =IF(ISBLANK(R41),ROUND(AVERAGEIF($Y$2:$Y$600,Y41,$R$2:$R$29),0),R41) -> 212.058 | AB41: =AA41*S41 -> 636.174 | AC41: =AB41*(1-T41) -> 445.3218 | AD41: CA | AE41: =MID(B41,4,4) -> 2015 | AF41: =RIGHT(B41,6) -> 117415
...

Sheet Cleaned Dataset
A1: SuperStore Sales Analysis
A2: Row ID | B2: Product ID | C2: Order ID | D2: CustomerName | E2: Customer ID | F2: Segment | G2: Order Date | H2: Country | I2: City and State | J2: Region | K2: Category | L2: Sub-Category | M2: Product Name | N2: Sales | O2: Quantity | P2: Discount | Q2: Profit | R2: Total Sales | S2: Revenue
A3: 1 | B3: FUR-BO-10001798 | C3: =_xlfn.XLOOKUP(B3,DataSet!$N$2:$N$600,DataSet!$AF$2:$AF$600,0) -> 152156 | D3: =_xlfn.XLOOKUP(B3,DataSet!$N$2:$N$600,DataSet!$G$2:$G$600,0) -> Claire Gute | E3: =_xlfn.XLOOKUP(B3,DataSet!$N$2:$N$600,DataSet!$F$2:$F$600,0) -> CG-12520 | F3: =_xlfn.XLOOKUP(B3,DataSet!$N$2:$N$600,DataSet!$W$2:$W$600,0) -> Consumer | G3: =_xlfn.XLOOKUP(B3,DataSet!$N$2:$N$600,DataSet!$C$2:$C$600,0) -> 42682 | H3: =_xlfn.XLOOKUP(B3,DataSet!$N$2:$N$600,DataSet!$I$2:$I$600,0) -> United States | I3: =_xlfn.XLOOKUP(B3,DataSet!$N$2:$N$600,DataSet!$X$2:$X$600,0) -> Henderson - Kentucky | J3: =_xlfn.XLOOKUP(B3,DataSet!$N$2:$N$600,DataSet!$M$2:$M$600,0) -> South | K3: =_xlfn.XLOOKUP(B3,DataSet!$N$2:$N$600,DataSet!$O$2:$O$600,0) -> Furniture | L3: =_xlfn.XLOOKUP(B3,DataSet!$N$2:$N$600,DataSet!$Y$2:$Y$600,0) -> Bookcases | M3: =_xlfn.XLOOKUP(B3,DataSet!$N$2:$N$600,DataSet!$Q$2:$Q$600,0) -> Bush Somerset Collection Bookcase | N3: =_xlfn.XLOOKUP(B3,DataSet!$N$2:$N$600,DataSet!$AA$2:$AA$600,0) -> 261.96 | O3: =_xlfn.XLOOKUP(B3,DataSet!$N$2:$N$600,DataSet!$S$2:$S$600,0) -> 2 | P3: =_xlfn.XLOOKUP(B3,DataSet!$N$2:$N$600,DataSet!$T$2:$T$600,0) -> 0 | Q3: =_xlfn.XLOOKUP(B3,DataSet!$N$2:$N$600,DataSet!$U$2:$U$600,0) -> 41.9136 | R3: =_xlfn.XLOOKUP(B3,DataSet!$N$2:$N$600,DataSet!$AB$2:$AB$600,0) -> 523.92 | S3: =_xlfn.XLOOKUP(B3,DataSet!$N$2:$N$600,DataSet!$AC$2:$AC$600,0) -> 523.92
A4: 2 | B4: FUR-CH-10000454 | C4: =_xlfn.XLOOKUP(B4,DataSet!$N$2:$N$600,DataSet!$AF$2:$AF$600,0) -> 152156 | D4: =_xlfn.XLOOKUP(B4,DataSet!$N$2:$N$600,DataSet!$G$2:$G$600,0) -> Claire Gute | E4: =_xlfn.XLOOKUP(B4,DataSet!$N$2:$N$600,DataSet!$F$2:$F$600,0) -> CG-12520 | F4: =_xlfn.XLOOKUP(B4,DataSet!$N$2:$N$600,DataSet!$W$2:$W$600,0) -> Consumer | G4: =_xlfn.XLOOKUP(B4,DataSet!$N$2:$N$600,DataSet!$C$2:$C$600,0) -> 42682 | H4: =_xlfn.XLOOKUP(B4,DataSet!$N$2:$N$600,DataSet!$I$2:$I$600,0) -> United States | I4: =_xlfn.XLOOKUP(B4,DataSet!$N$2:$N$600,DataSet!$X$2:$X$600,0) -> Henderson - Kentucky | J4: =_xlfn.XLOOKUP(B4,DataSet!$N$2:$N$600,DataSet!$M$2:$M$600,0) -> South | K4: =_xlfn.XLOOKUP(B4,DataSet!$N$2:$N$600,DataSet!$O$2:$O$600,0) -> Furniture | L4: =_xlfn.XLOOKUP(B4,DataSet!$N$2:$N$600,DataSet!$Y$2:$Y$600,0) -> Chairs | M4: =_xlfn.XLOOKUP(B4,DataSet!$N$2:$N$600,DataSet!$Q$2:$Q$600,0) -> Hon Deluxe Fabric Upholstered Stacking Chairs, Rounded Back | N4: =_xlfn.XLOOKUP(B4,DataSet!$N$2:$N$600,DataSet!$AA$2:$AA$600,0) -> 731.94 | O4: =_xlfn.XLOOKUP(B4,DataSet!$N$2:$N$600,DataSet!$S$2:$S$600,0) -> 3 | P4: =_xlfn.XLOOKUP(B4,DataSet!$N$2:$N$600,DataSet!$T$2:$T$600,0) -> 0 | Q4: =_xlfn.XLOOKUP(B4,DataSet!$N$2:$N$600,DataSet!$U$2:$U$600,0) -> 219.582 | R4: =_xlfn.XLOOKUP(B4,DataSet!$N$2:$N$600,DataSet!$AB$2:$AB$600,0) -> 2195.82 | S4: =_xlfn.XLOOKUP(B4,DataSet!$N$2:$N$600,DataSet!$AC$2:$AC$600,0) -> 2195.82
A5: 3 | B5: OFF-LA-10000240 | C5: =_xlfn.XLOOKUP(B5,DataSet!$N$2:$N$600,DataSet!$AF$2:$AF$600,0) -> 138688 | D5: =_xlfn.XLOOKUP(B5,DataSet!$N$2:$N$600,DataSet!$G$2:$G$600,0) -> Darrin Van Huff | E5: =_xlfn.XLOOKUP(B5,DataSet!$N$2:$N$600,DataSet!$F$2:$F$600,0) -> DV-13045 | F5: =_xlfn.XLOOKUP(B5,DataSet!$N$2:$N$600,DataSet!$W$2:$W$600,0) -> Corporate | G5: =_xlfn.XLOOKUP(B5,DataSet!$N$2:$N$600,DataSet!$C$2:$C$600,0) -> 42533 | H5: =_xlfn.XLOOKUP(B5,DataSet!$N$2:$N$600,DataSet!$I$2:$I$600,0) -> United States | I5: =_xlfn.XLOOKUP(B5,DataSet!$N$2:$N$600,DataSet!$X$2:$X$600,0) -> Los Angeles - California | J5: =_xlfn.XLOOKUP(B5,DataSet!$N$2:$N$600,DataSet!$M$2:$M$600,0) -> West | K5: =_xlfn.XLOOKUP(B5,DataSet!$N$2:$N$600,DataSet!$O$2:$O$600,0) -> Office Supplies | L5: =_xlfn.XLOOKUP(B5,DataSet!$N$2:$N$600,DataSet!$Y$2:$Y$600,0) -> Labels | M5: =_xlfn.XLOOKUP(B5,DataSet!$N$2:$N$600,DataSet!$Q$2:$Q$600,0) -> Self-Adhesive Address Labels for Typewriters by Universal | N5: =_xlfn.XLOOKUP(B5,DataSet!$N$2:$N$600,DataSet!$AA$2:$AA$600,0) -> 14.62 | O5: =_xlfn.XLOOKUP(B5,DataSet!$N$2:$N$600,DataSet!$S$2:$S$600,0) -> 2 | P5: =_xlfn.XLOOKUP(B5,DataSet!$N$2:$N$600,DataSet!$T$2:$T$600,0) -> 0 | Q5: =_xlfn.XLOOKUP(B5,DataSet!$N$2:$N$600,DataSet!$U$2:$U$600,0) -> 6.8714 | R5: =_xlfn.XLOOKUP(B5,DataSet!$N$2:$N$600,DataSet!$AB$2:$AB$600,0) -> 29.24 | S5: =_xlfn.XLOOKUP(B5,DataSet!$N$2:$N$600,DataSet!$AC$2:$AC$600,0) -> 29.24
A6: 4 | B6: FUR-TA-10000577 | C6: =_xlfn.XLOOKUP(B6,DataSet!$N$2:$N$600,DataSet!$AF$2:$AF$600,0) -> 108966 | D6: =_xlfn.XLOOKUP(B6,DataSet!$N$2:$N$600,DataSet!$G$2:$G$600,0) -> Sean O'Donnell | E6: =_xlfn.XLOOKUP(B6,DataSet!$N$2:$N$600,DataSet!$F$2:$F$600,0) -> SO-20335 | F6: =_xlfn.XLOOKUP(B6,DataSet!$N$2:$N$600,DataSet!$W$2:$W$600,0) -> Consumer | G6: =_xlfn.XLOOKUP(B6,DataSet!$N$2:$N$600,DataSet!$C$2:$C$600,0) -> 42288 | H6: =_xlfn.XLOOKUP(B6,DataSet!$N$2:$N$600,DataSet!$I$2:$I$600,0) -> United States | I6: =_xlfn.XLOOKUP(B6,DataSet!$N$2:$N$600,DataSet!$X$2:$X$600,0) -> Fort Lauderdale - Florida | J6: =_xlfn.XLOOKUP(B6,DataSet!$N$2:$N$600,DataSet!$M$2:$M$600,0) -> South | K6: =_xlfn.XLOOKUP(B6,DataSet!$N$2:$N$600,DataSet!$O$2:$O$600,0) -> Furniture | L6: =_xlfn.XLOOKUP(B6,DataSet!$N$2:$N$600,DataSet!$Y$2:$Y$600,0) -> Tables | M6: =_xlfn.XLOOKUP(B6,DataSet!$N$2:$N$600,DataSet!$Q$2:$Q$600,0) -> Bretford CR4500 Series Slim Rectangular Table | N6: =_xlfn.XLOOKUP(B6,DataSet!$N$2:$N$600,DataSet!$AA$2:$AA$600,0) -> 957.5775 | O6: =_xlfn.XLOOKUP(B6,DataSet!$N$2:$N$600,DataSet!$S$2:$S$600,0) -> 5 | P6: =_xlfn.XLOOKUP(B6,DataSet!$N$2:$N$600,DataSet!$T$2:$T$600,0) -> 0.45 | Q6: =_xlfn.XLOOKUP(B6,DataSet!$N$2:$N$600,DataSet!$U$2:$U$600,0) -> -383.031 | R6: =_xlfn.XLOOKUP(B6,DataSet!$N$2:$N$600,DataSet!$AB$2:$AB$600,0) -> 4787.8875 | S6: =_xlfn.XLOOKUP(B6,DataSet!$N$2:$N$600,DataSet!$AC$2:$AC$600,0) -> 2633.3381
A7: 5 | B7: OFF-ST-10000760 | C7: =_xlfn.XLOOKUP(B7,DataSet!$N$2:$N$600,DataSet!$AF$2:$AF$600,0) -> 108966 | D7: =_xlfn.XLOOKUP(B7,DataSet!$N$2:$N$600,DataSet!$G$2:$G$600,0) -> Sean O'Donnell | E7: =_xlfn.XLOOKUP(B7,DataSet!$N$2:$N$600,DataSet!$F$2:$F$600,0) -> SO-20335 | F7: =_xlfn.XLOOKUP(B7,DataSet!$N$2:$N$600,DataSet!$W$2:$W$600,0) -> Consumer | G7: =_xlfn.XLOOKUP(B7,DataSet!$N$2:$N$600,DataSet!$C$2:$C$600,0) -> 42288 | H7: =_xlfn.XLOOKUP(B7,DataSet!$N$2:$N$600,DataSet!$I$2:$I$600,0) -> United States | I7: =_xlfn.XLOOKUP(B7,DataSet!$N$2:$N$600,DataSet!$X$2:$X$600,0) -> Fort Lauderdale - Florida | J7: =_xlfn.XLOOKUP(B7,DataSet!$N$2:$N$600,DataSet!$M$2:$M$600,0) -> South | K7: =_xlfn.XLOOKUP(B7,DataSet!$N$2:$N$600,DataSet!$O$2:$O$600,0) -> Office Supplies | L7: =_xlfn.XLOOKUP(B7,DataSet!$N$2:$N$600,DataSet!$Y$2:$Y$600,0) -> Storage | M7: =_xlfn.XLOOKUP(B7,DataSet!$N$2:$N$600,DataSet!$Q$2:$Q$600,0) -> Eldon Fold 'N Roll Cart System | N7: =_xlfn.XLOOKUP(B7,DataSet!$N$2:$N$600,DataSet!$AA$2:$AA$600,0) -> 22.368 | O7: =_xlfn.XLOOKUP(B7,DataSet!$N$2:$N$600,DataSet!$S$2:$S$600,0) -> 2 | P7: =_xlfn.XLOOKUP(B7,DataSet!$N$2:$N$600,DataSet!$T$2:$T$600,0) -> 0.2 | Q7: =_xlfn.XLOOKUP(B7,DataSet!$N$2:$N$600,DataSet!$U$2:$U$600,0) -> 2.5164 | R7: =_xlfn.XLOOKUP(B7,DataSet!$N$2:$N$600,DataSet!$AB$2:$AB$600,0) -> 44.736 | S7: =_xlfn.XLOOKUP(B7,DataSet!$N$2:$N$600,DataSet!$AC$2:$AC$600,0) -> 35.7888
A8: 6 | B8: FUR-FU-10001487 | C8: =_xlfn.XLOOKUP(B8,DataSet!$N$2:$N$600,DataSet!$AF$2:$AF$600,0) -> 115812 | D8: =_xlfn.XLOOKUP(B8,DataSet!$N$2:$N$600,DataSet!$G$2:$G$600,0) -> Brosina Hoffman | E8: =_xlfn.XLOOKUP(B8,DataSet!$N$2:$N$600,DataSet!$F$2:$F$600,0) -> BH-11710 | F8: =_xlfn.XLOOKUP(B8,DataSet!$N$2:$N$600,DataSet!$W$2:$W$600,0) -> Consumer | G8: =_xlfn.XLOOKUP(B8,DataSet!$N$2:$N$600,DataSet!$C$2:$C$600,0) -> 41799 | H8: =_xlfn.XLOOKUP(B8,DataSet!$N$2:$N$600,DataSet!$I$2:$I$600,0) -> United States | I8: =_xlfn.XLOOKUP(B8,DataSet!$N$2:$N$600,DataSet!$X$2:$X$600,0) -> Los Angeles - California | J8: =_xlfn.XLOOKUP(B8,DataSet!$N$2:$N$600,DataSet!$M$2:$M$600,0) -> West | K8: =_xlfn.XLOOKUP(B8,DataSet!$N$2:$N$600,DataSet!$O$2:$O$600,0) -> Furniture | L8: =_xlfn.XLOOKUP(B8,DataSet!$N$2:$N$600,DataSet!$Y$2:$Y$600,0) -> Furnishings | M8: =_xlfn.XLOOKUP(B8,DataSet!$N$2:$N$600,DataSet!$Q$2:$Q$600,0) -> Eldon Expressions Wood and Plastic Desk Accessories, Cherry Wood | N8: =_xlfn.XLOOKUP(B8,DataSet!$N$2:$N$600,DataSet!$AA$2:$AA$600,0) -> 48.86 | O8: =_xlfn.XLOOKUP(B8,DataSet!$N$2:$N$600,DataSet!$S$2:$S$600,0) -> 7 | P8: =_xlfn.XLOOKUP(B8,DataSet!$N$2:$N$600,DataSet!$T$2:$T$600,0) -> 0 | Q8: =_xlfn.XLOOKUP(B8,DataSet!$N$2:$N$600,DataSet!$U$2:$U$600,0) -> 14.1694 | R8: =_xlfn.XLOOKUP(B8,DataSet!$N$2:$N$600,DataSet!$AB$2:$AB$600,0) -> 342.02 | S8: =_xlfn.XLOOKUP(B8,DataSet!$N$2:$N$600,DataSet!$AC$2:$AC$600,0) -> 342.02
A9: 7 | B9: OFF-AR-10002833 | C9: =_xlfn.XLOOKUP(B9,DataSet!$N$2:$N$600,DataSet!$AF$2:$AF$600,0) -> 115812 | D9: =_xlfn.XLOOKUP(B9,DataSet!$N$2:$N$600,DataSet!$G$2:$G$600,0) -> Brosina Hoffman | E9: =_xlfn.XLOOKUP(B9,DataSet!$N$2:$N$600,DataSet!$F$2:$F$600,0) -> BH-11710 | F9: =_xlfn.XLOOKUP(B9,DataSet!$N$2:$N$600,DataSet!$W$2:$W$600,0) -> Consumer | G9: =_xlfn.XLOOKUP(B9,DataSet!$N$2:$N$600,DataSet!$C$2:$C$600,0) -> 41799 | H9: =_xlfn.XLOOKUP(B9,DataSet!$N$2:$N$600,DataSet!$I$2:$I$600,0) -> United States | I9: =_xlfn.XLOOKUP(B9,DataSet!$N$2:$N$600,DataSet!$X$2:$X$600,0) -> Los Angeles - California | J9: =_xlfn.XLOOKUP(B9,DataSet!$N$2:$N$600,DataSet!$M$2:$M$600,0) -> West | K9: =_xlfn.XLOOKUP(B9,DataSet!$N$2:$N$600,DataSet!$O$2:$O$600,0) -> Office Supplies | L9: =_xlfn.XLOOKUP(B9,DataSet!$N$2:$N$600,DataSet!$Y$2:$Y$600,0) -> Art | M9: =_xlfn.XLOOKUP(B9,DataSet!$N$2:$N$600,DataSet!$Q$2:$Q$600,0) -> Newell 322 | N9: =_xlfn.XLOOKUP(B9,DataSet!$N$2:$N$600,DataSet!$AA$2:$AA$600,0) -> 7.28 | O9: =_xlfn.XLOOKUP(B9,DataSet!$N$2:$N$600,DataSet!$S$2:$S$600,0) -> 4 | P9: =_xlfn.XLOOKUP(B9,DataSet!$N$2:$N$600,DataSet!$T$2:$T$600,0) -> 0 | Q9: =_xlfn.XLOOKUP(B9,DataSet!$N$2:$N$600,DataSet!$U$2:$U$600,0) -> 1.9656 | R9: =_xlfn.XLOOKUP(B9,DataSet!$N$2:$N$600,DataSet!$AB$2:$AB$600,0) -> 29.12 | S9: =_xlfn.XLOOKUP(B9,DataSet!$N$2:$N$600,DataSet!$AC$2:$AC$600,0) -> 29.12
A10: 8 | B10: TEC-PH-10002275 | C10: =_xlfn.XLOOKUP(B10,DataSet!$N$2:$N$600,DataSet!$AF$2:$AF$600,0) -> 115812 | D10: =_xlfn.XLOOKUP(B10,DataSet!$N$2:$N$600,DataSet!$G$2:$G$600,0) -> Brosina Hoffman | E10: =_xlfn.XLOOKUP(B10,DataSet!$N$2:$N$600,DataSet!$F$2:$F$600,0) -> BH-11710 | F10: =_xlfn.XLOOKUP(B10,DataSet!$N$2:$N$600,DataSet!$W$2:$W$600,0) -> Consumer | G10: =_xlfn.XLOOKUP(B10,DataSet!$N$2:$N$600,DataSet!$C$2:$C$600,0) -> 41799 | H10: =_xlfn.XLOOKUP(B10,DataSet!$N$2:$N$600,DataSet!$I$2:$I$600,0) -> United States | I10: =_xlfn.XLOOKUP(B10,DataSet!$N$2:$N$600,DataSet!$X$2:$X$600,0) -> Los Angeles - California | J10: =_xlfn.XLOOKUP(B10,DataSet!$N$2:$N$600,DataSet!$M$2:$M$600,0) -> West | K10: =_xlfn.XLOOKUP(B10,DataSet!$N$2:$N$600,DataSet!$O$2:$O$600,0) -> Technology | L10: =_xlfn.XLOOKUP(B10,DataSet!$N$2:$N$600,DataSet!$Y$2:$Y$600,0) -> Phones | M10: =_xlfn.XLOOKUP(B10,DataSet!$N$2:$N$600,DataSet!$Q$2:$Q$600,0) -> Mitel 5320 IP Phone VoIP phone | N10: =_xlfn.XLOOKUP(B10,DataSet!$N$2:$N$600,DataSet!$AA$2:$AA$600,0) -> 907.152 | O10: =_xlfn.XLOOKUP(B10,DataSet!$N$2:$N$600,DataSet!$S$2:$S$600,0) -> 6 | P10: =_xlfn.XLOOKUP(B10,DataSet!$N$2:$N$600,DataSet!$T$2:$T$600,0) -> 0.2 | Q10: =_xlfn.XLOOKUP(B10,DataSet!$N$2:$N$600,DataSet!$U$2:$U$600,0) -> 90.7152 | R10: =_xlfn.XLOOKUP(B10,DataSet!$N$2:$N$600,DataSet!$AB$2:$AB$600,0) -> 5442.912 | S10: =_xlfn.XLOOKUP(B10,DataSet!$N$2:$N$600,DataSet!$AC$2:$AC$600,0) -> 4354.3296
A11: 9 | B11: OFF-BI-10003910 | C11: =_xlfn.XLOOKUP(B11,DataSet!$N$2:$N$600,DataSet!$AF$2:$AF$600,0) -> 115812 | D11: =_xlfn.XLOOKUP(B11,DataSet!$N$2:$N$600,DataSet!$G$2:$G$600,0) -> Brosina Hoffman | E11: =_xlfn.XLOOKUP(B11,DataSet!$N$2:$N$600,DataSet!$F$2:$F$600,0) -> BH-11710 | F11: =_xlfn.XLOOKUP(B11,DataSet!$N$2:$N$600,DataSet!$W$2:$W$600,0) -> Consumer | G11: =_xlfn.XLOOKUP(B11,DataSet!$N$2:$N$600,DataSet!$C$2:$C$600,0) -> 41799 | H11: =_xlfn.XLOOKUP(B11,DataSet!$N$2:$N$600,DataSet!$I$2:$I$600,0) -> United States | I11: =_xlfn.XLOOKUP(B11,DataSet!$N$2:$N$600,DataSet!$X$2:$X$600,0) -> Los Angeles - California | J11: =_xlfn.XLOOKUP(B11,DataSet!$N$2:$N$600,DataSet!$M$2:$M$600,0) -> West | K11: =_xlfn.XLOOKUP(B11,DataSet!$N$2:$N$600,DataSet!$O$2:$O$600,0) -> Office Supplies | L11: =_xlfn.XLOOKUP(B11,DataSet!$N$2:$N$600,DataSet!$Y$2:$Y$600,0) -> Binders | M11: =_xlfn.XLOOKUP(B11,DataSet!$N$2:$N$600,DataSet!$Q$2:$Q$600,0) -> DXL Angle-View Binders with Locking Rings by Samsill | N11: =_xlfn.XLOOKUP(B11,DataSet!$N$2:$N$600,DataSet!$AA$2:$AA$600,0) -> 18.504 | O11: =_xlfn.XLOOKUP(B11,DataSet!$N$2:$N$600,DataSet!$S$2:$S$600,0) -> 3 | P11: =_xlfn.XLOOKUP(B11,DataSet!$N$2:$N$600,DataSet!$T$2:$T$600,0) -> 0.2 | Q11: =_xlfn.XLOOKUP(B11,DataSet!$N$2:$N$600,DataSet!$U$2:$U$600,0) -> 5.7825 | R11: =_xlfn.XLOOKUP(B11,DataSet!$N$2:$N$600,DataSet!$AB$2:$AB$600,0) -> 55.512 | S11: =_xlfn.XLOOKUP(B11,DataSet!$N$2:$N$600,DataSet!$AC$2:$AC$600,0) -> 44.4096
A12: 10 | B12: OFF-AP-10002892 | C12: =_xlfn.XLOOKUP(B12,DataSet!$N$2:$N$600,DataSet!$AF$2:$AF$600,0) -> 115812 | D12: =_xlfn.XLOOKUP(B12,DataSet!$N$2:$N$600,DataSet!$G$2:$G$600,0) -> Brosina Hoffman | E12: =_xlfn.XLOOKUP(B12,DataSet!$N$2:$N$600,DataSet!$F$2:$F$600,0) -> BH-11710 | F12: =_xlfn.XLOOKUP(B12,DataSet!$N$2:$N$600,DataSet!$W$2:$W$600,0) -> Consumer | G12: =_xlfn.XLOOKUP(B12,DataSet!$N$2:$N$600,DataSet!$C$2:$C$600,0) -> 41799 | H12: =_xlfn.XLOOKUP(B12,DataSet!$N$2:$N$600,DataSet!$I$2:$I$600,0) -> United States | I12: =_xlfn.XLOOKUP(B12,DataSet!$N$2:$N$600,DataSet!$X$2:$X$600,0) -> Los Angeles - California | J12: =_xlfn.XLOOKUP(B12,DataSet!$N$2:$N$600,DataSet!$M$2:$M$600,0) -> West | K12: =_xlfn.XLOOKUP(B12,DataSet!$N$2:$N$600,DataSet!$O$2:$O$600,0) -> Office Supplies | L12: =_xlfn.XLOOKUP(B12,DataSet!$N$2:$N$600,DataSet!$Y$2:$Y$600,0) -> Appliances | M12: =_xlfn.XLOOKUP(B12,DataSet!$N$2:$N$600,DataSet!$Q$2:$Q$600,0) -> Belkin F5C206VTEL 6 Outlet Surge | N12: =_xlfn.XLOOKUP(B12,DataSet!$N$2:$N$600,DataSet!$AA$2:$AA$600,0) -> 114.9 | O12: =_xlfn.XLOOKUP(B12,DataSet!$N$2:$N$600,DataSet!$S$2:$S$600,0) -> 5 | P12: =_xlfn.XLOOKUP(B12,DataSet!$N$2:$N$600,DataSet!$T$2:$T$600,0) -> 0 | Q12: =_xlfn.XLOOKUP(B12,DataSet!$N$2:$N$600,DataSet!$U$2:$U$600,0) -> 34.47 | R12: =_xlfn.XLOOKUP(B12,DataSet!$N$2:$N$600,DataSet!$AB$2:$AB$600,0) -> 574.5 | S12: =_xlfn.XLOOKUP(B12,DataSet!$N$2:$N$600,DataSet!$AC$2:$AC$600,0) -> 574.5
A13: 11 | B13: FUR-TA-10001539 | C13: =_xlfn.XLOOKUP(B13,DataSet!$N$2:$N$600,DataSet!$AF$2:$AF$600,0) -> 115812 | D13: =_xlfn.XLOOKUP(B13,DataSet!$N$2:$N$600,DataSet!$G$2:$G$600,0) -> Brosina Hoffman | E13: =_xlfn.XLOOKUP(B13,DataSet!$N$2:$N$600,DataSet!$F$2:$F$600,0) -> BH-11710 | F13: =_xlfn.XLOOKUP(B13,DataSet!$N$2:$N$600,DataSet!$W$2:$W$600,0) -> Consumer | G13: =_xlfn.XLOOKUP(B13,DataSet!$N$2:$N$600,DataSet!$C$2:$C$600,0) -> 41799 | H13: =_xlfn.XLOOKUP(B13,DataSet!$N$2:$N$600,DataSet!$I$2:$I$600,0) -> United States | I13: =_xlfn.XLOOKUP(B13,DataSet!$N$2:$N$600,DataSet!$X$2:$X$600,0) -> Los Angeles - California | J13: =_xlfn.XLOOKUP(B13,DataSet!$N$2:$N$600,DataSet!$M$2:$M$600,0) -> West | K13: =_xlfn.XLOOKUP(B13,DataSet!$N$2:$N$600,DataSet!$O$2:$O$600,0) -> Furniture | L13: =_xlfn.XLOOKUP(B13,DataSet!$N$2:$N$600,DataSet!$Y$2:$Y$600,0) -> Tables | M13: =_xlfn.XLOOKUP(B13,DataSet!$N$2:$N$600,DataSet!$Q$2:$Q$600,0) -> Chromcraft Rectangular Conference Tables | N13: =_xlfn.XLOOKUP(B13,DataSet!$N$2:$N$600,DataSet!$AA$2:$AA$600,0) -> 1706.184 | O13: =_xlfn.XLOOKUP(B13,DataSet!$N$2:$N$600,DataSet!$S$2:$S$600,0) -> 9 | P13: =_xlfn.XLOOKUP(B13,DataSet!$N$2:$N$600,DataSet!$T$2:$T$600,0) -> 0.2 | Q13: =_xlfn.XLOOKUP(B13,DataSet!$N$2:$N$600,DataSet!$U$2:$U$600,0) -> 85.3092 | R13: =_xlfn.XLOOKUP(B13,DataSet!$N$2:$N$600,DataSet!$AB$2:$AB$600,0) -> 15355.656 | S13: =_xlfn.XLOOKUP(B13,DataSet!$N$2:$N$600,DataSet!$AC$2:$AC$600,0) -> 12284.525
A14: 12 | B14: TEC-PH-10002033 | C14: =_xlfn.XLOOKUP(B14,DataSet!$N$2:$N$600,DataSet!$AF$2:$AF$600,0) -> 115812 | D14: =_xlfn.XLOOKUP(B14,DataSet!$N$2:$N$600,DataSet!$G$2:$G$600,0) -> Brosina Hoffman | E14: =_xlfn.XLOOKUP(B14,DataSet!$N$2:$N$600,DataSet!$F$2:$F$600,0) -> BH-11710 | F14: =_xlfn.XLOOKUP(B14,DataSet!$N$2:$N$600,DataSet!$W$2:$W$600,0) -> Consumer | G14: =_xlfn.XLOOKUP(B14,DataSet!$N$2:$N$600,DataSet!$C$2:$C$600,0) -> 41799 | H14: =_xlfn.XLOOKUP(B14,DataSet!$N$2:$N$600,DataSet!$I$2:$I$600,0) -> United States | I14: =_xlfn.XLOOKUP(B14,DataSet!$N$2:$N$600,DataSet!$X$2:$X$600,0) -> Los Angeles - California | J14: =_xlfn.XLOOKUP(B14,DataSet!$N$2:$N$600,DataSet!$M$2:$M$600,0) -> West | K14: =_xlfn.XLOOKUP(B14,DataSet!$N$2:$N$600,DataSet!$O$2:$O$600,0) -> Technology | L14: =_xlfn.XLOOKUP(B14,DataSet!$N$2:$N$600,DataSet!$Y$2:$Y$600,0) -> Phones | M14: =_xlfn.XLOOKUP(B14,DataSet!$N$2:$N$600,DataSet!$Q$2:$Q$600,0) -> Konftel 250 Conference phone - Charcoal black | N14: =_xlfn.XLOOKUP(B14,DataSet!$N$2:$N$600,DataSet!$AA$2:$AA$600,0) -> 911.424 | O14: =_xlfn.XLOOKUP(B14,DataSet!$N$2:$N$600,DataSet!$S$2:$S$600,0) -> 4 | P14: =_xlfn.XLOOKUP(B14,DataSet!$N$2:$N$600,DataSet!$T$2:$T$600,0) -> 0.2 | Q14: =_xlfn.XLOOKUP(B14,DataSet!$N$2:$N$600,DataSet!$U$2:$U$600,0) -> 68.3568 | R14: =_xlfn.XLOOKUP(B14,DataSet!$N$2:$N$600,DataSet!$AB$2:$AB$600,0) -> 3645.696 | S14: =_xlfn.XLOOKUP(B14,DataSet!$N$2:$N$600,DataSet!$AC$2:$AC$600,0) -> 2916.5568
... A601: 599 | B601: OFF-SU-10004115 | C601: =_xlfn.XLOOKUP(B601,DataSet!$N$2:$N$600,DataSet!$AF$2:$AF$600,0) -> 120180 | D601: =_xlfn.XLOOKUP(B601,DataSet!$N$2:$N$600,DataSet!$G$2:$G$600,0) -> Theone Pippenger | E601: =_xlfn.XLOOKUP(B601,DataSet!$N$2:$N$600,DataSet!$F$2:$F$600,0) -> TP-21130 | F601: =_xlfn.XLOOKUP(B601,DataSet!$N$2:$N$600,DataSet!$W$2:$W$600,0) -> Consumer | G601: =_xlfn.XLOOKUP(B601,DataSet!$N$2:$N$600,DataSet!$C$2:$C$600,0) -> 42565 | H601: =_xlfn.XLOOKUP(B601,DataSet!$N$2:$N$600,DataSet!$I$2:$I$600,0) -> United States | I601: =_xlfn.XLOOKUP(B601,DataSet!$N$2:$N$600,DataSet!$X$2:$X$600,0) -> Philadelphia - Pennsylvania | J601: =_xlfn.XLOOKUP(B601,DataSet!$N$2:$N$600,DataSet!$M$2:$M$600,0) -> East | K601: =_xlfn.XLOOKUP(B601,DataSet!$N$2:$N$600,DataSet!$O$2:$O$600,0) -> Office Supplies | L601: =_xlfn.XLOOKUP(B601,DataSet!$N$2:$N$600,DataSet!$Y$2:$Y$600,0) -> Supplies | M601: =_xlfn.XLOOKUP(B601,DataSet!$N$2:$N$600,DataSet!$Q$2:$Q$600,0) -> Acme Stainless Steel Office Snips | N601: =_xlfn.XLOOKUP(B601,DataSet!$N$2:$N$600,DataSet!$AA$2:$AA$600,0) -> 11.632 | O601: =_xlfn.XLOOKUP(B601,DataSet!$N$2:$N$600,DataSet!$S$2:$S$600,0) -> 2 | P601: =_xlfn.XLOOKUP(B601,DataSet!$N$2:$N$600,DataSet!$T$2:$T$600,0) -> 0.2 | Q601: =_xlfn.XLOOKUP(B601,DataSet!$N$2:$N$600,DataSet!$U$2:$U$600,0) -> 1.0178 | R601: =_xlfn.XLOOKUP(B601,DataSet!$N$2:$N$600,DataSet!$AB$2:$AB$600,0) -> 23.264 | S601: =_xlfn.XLOOKUP(B601,DataSet!$N$2:$N$600,DataSet!$AC$2:$AC$600,0) -> 18.6112
